Workbook

Sheet Dashboard
A1: Endocrine Block — Progress Tracker
A2: Built from GUSOM-Endocrine-ProgressTracker.html — Upload to Google Sheets to keep using formulas.
A4: How to use | B4: Checklist Progress | E4: Lectures Planned | H4: 3rd-Party Selections | K4: UWorld Progress
A5: 1) Use the Planner tab to choose LEC plus up to 2 third-party resources per lecture. | B5: =IFERROR(COUNTIFS(Checklist!$I$5:$I$191,TRUE(),Checklist!$H$5:$H$191,TRUE())/COUNTIF(Checklist!$H$5:$H$191,TRUE()),0) -> 0 | E5: =COUNTIF(Planner!$D$5:$D$29,"Yes") -> 0 | H5: =COUNTA(Planner!$E$5:$F$29) -> 0 | K5: =IFERROR(SUM(UWorld!$F$5:$F$29)/SUM(UWorld!$E$5:$E$29),0) -> 0
A6: 2) Mark Done? on the Checklist tab for tasks you complete. | B6: =COUNTIFS(Checklist!$H$5:$H$191,TRUE(),Checklist!$I$5:$I$191,TRUE())&" done / "&COUNTIF(Checklist!$H$5:$H$191,TRUE())&" included" -> 0 done / 25 included | E6: =COUNTIF(Planner!$D$5:$D$29,"Yes")&" of 25 lectures" -> 0 of 25 lectures | H6: =COUNTA(Planner!$E$5:$F$29)&" resource slots filled" -> 0 resource slots filled | K6: =SUM(UWorld!$F$5:$F$29)&" done / "&SUM(UWorld!$E$5:$E$29)&" assigned" -> 0 done / 392 assigned
A7: 3) Enter UWorld progress on the UWorld tab.
A8: 4) Filter Study Order to Included? = TRUE for your active queue.
A10: Date | B10: Subject | C10: Lecture | D10: Planner Status | E10: Est. Time (min) | F10: Checklist % | G10: UWorld Assigned | H10: UWorld Done
A11: 46132 | B11: Biochem | C11: Introduction to Hormones | D11: =Planner!G5 -> Not Started | E11: =SUMPRODUCT(--(Checklist!$H$5:$H$8=TRUE()),Checklist!$G$5:$G$8) -> 15 | F11: =IFERROR(COUNTIFS(Checklist!$I$5:$I$8,TRUE(),Checklist!$H$5:$H$8,TRUE())/COUNTIF(Checklist!$H$5:$H$8,TRUE()),0) -> 0 | G11: =UWorld!E5 -> 42 | H11: =UWorld!F5 -> 0
A12: 46132 | B12: Phys | C12: Hypothalamic Pituitary Relationships I | D12: =Planner!G6 -> Not Started | E12: =SUMPRODUCT(--(Checklist!$H$9:$H$14=TRUE()),Checklist!$G$9:$G$14) -> 15 | F12: =IFERROR(COUNTIFS(Checklist!$I$9:$I$14,TRUE(),Checklist!$H$9:$H$14,TRUE())/COUNTIF(Checklist!$H$9:$H$14,TRUE()),0) -> 0 | G12: =UWorld!E6 -> 4 | H12: =UWorld!F6 -> 0
A13: 46135 | B13: Biochem | C13: Adrenal Hormone Synthesis and Action | D13: =Planner!G7 -> Not Started | E13: =SUMPRODUCT(--(Checklist!$H$15:$H$20=TRUE()),Checklist!$G$15:$G$20) -> 15 | F13: =IFERROR(COUNTIFS(Checklist!$I$15:$I$20,TRUE(),Checklist!$H$15:$H$20,TRUE())/COUNTIF(Checklist!$H$15:$H$20,TRUE()),0) -> 0 | G13: =UWorld!E7 -> 11 | H13: =UWorld!F7 -> 0
A14: 46135 | B14: Biochem | C14: Sex Steroid Synthesis and Action | D14: =Planner!G8 -> Not Started | E14: =SUMPRODUCT(--(Checklist!$H$21:$H$25=TRUE()),Checklist!$G$21:$G$25) -> 15 | F14: =IFERROR(COUNTIFS(Checklist!$I$21:$I$25,TRUE(),Checklist!$H$21:$H$25,TRUE())/COUNTIF(Checklist!$H$21:$H$25,TRUE()),0) -> 0 | G14: =UWorld!E8 -> 14 | H14: =UWorld!F8 -> 0
A15: 46134 | B15: Phys | C15: Hypothalamic Pituitary Relationships II | D15: =Planner!G9 -> Not Started | E15: =SUMPRODUCT(--(Checklist!$H$26:$H$32=TRUE()),Checklist!$G$26:$G$32) -> 15 | F15: =IFERROR(COUNTIFS(Checklist!$I$26:$I$32,TRUE(),Checklist!$H$26:$H$32,TRUE())/COUNTIF(Checklist!$H$26:$H$32,TRUE()),0) -> 0 | G15: =UWorld!E9 -> 4 | H15: =UWorld!F9 -> 0
A16: 46140 | B16: Biochem | C16: Posterior Pituitary Hormones | D16: =Planner!G10 -> Not Started | E16: =SUMPRODUCT(--(Checklist!$H$33:$H$41=TRUE()),Checklist!$G$33:$G$41) -> 15 | F16: =IFERROR(COUNTIFS(Checklist!$I$33:$I$41,TRUE(),Checklist!$H$33:$H$41,TRUE())/COUNTIF(Checklist!$H$33:$H$41,TRUE()),0) -> 0 | G16: =UWorld!E10 -> 5 | H16: =UWorld!F10 -> 0
A17: 46141 | B17: Path | C17: Pituitary Pathology | D17: =Planner!G11 -> Not Started | E17: =SUMPRODUCT(--(Checklist!$H$42:$H$49=TRUE()),Checklist!$G$42:$G$49) -> 15 | F17: =IFERROR(COUNTIFS(Checklist!$I$42:$I$49,TRUE(),Checklist!$H$42:$H$49,TRUE())/COUNTIF(Checklist!$H$42:$H$49,TRUE()),0) -> 0 | G17: =UWorld!E11 -> 17 | H17: =UWorld!F11 -> 0
A18: 46156 | B18: Pharm | C18: Diagnosis & Treatment of Pituitary Disorders | D18: =Planner!G12 -> Not Started | E18: =SUMPRODUCT(--(Checklist!$H$50:$H$58=TRUE()),Checklist!$G$50:$G$58) -> 15 | F18: =IFERROR(COUNTIFS(Checklist!$I$50:$I$58,TRUE(),Checklist!$H$50:$H$58,TRUE())/COUNTIF(Checklist!$H$50:$H$58,TRUE()),0) -> 0 | G18: =UWorld!E12 -> 17 | H18: =UWorld!F12 -> 0
A19: 46157 | B19: Phys | C19: Hypothalamic-Pituitary-GH Axis | D19: =Planner!G13 -> Not Started | E19: =SUMPRODUCT(--(Checklist!$H$59:$H$66=TRUE()),Checklist!$G$59:$G$66) -> 15 | F19: =IFERROR(COUNTIFS(Checklist!$I$59:$I$66,TRUE(),Checklist!$H$59:$H$66,TRUE())/COUNTIF(Checklist!$H$59:$H$66,TRUE()),0) -> 0 | G19: =UWorld!E13 -> 2 | H19: =UWorld!F13 -> 0
A20: 46154 | B20: Biochem | C20: Thyroid Hormone Synthesis and Action | D20: =Planner!G14 -> Not Started | E20: =SUMPRODUCT(--(Checklist!$H$67:$H$72=TRUE()),Checklist!$G$67:$G$72) -> 15 | F20: =IFERROR(COUNTIFS(Checklist!$I$67:$I$72,TRUE(),Checklist!$H$67:$H$72,TRUE())/COUNTIF(Checklist!$H$67:$H$72,TRUE()),0) -> 0 | G20: =UWorld!E14 -> 1 | H20: =UWorld!F14 -> 0
A21: 46154 | B21: Hist | C21: Thyroid, Parathyroid & Adrenal Histology | D21: =Planner!G15 -> Not Started | E21: =SUMPRODUCT(--(Checklist!$H$73:$H$92=TRUE()),Checklist!$G$73:$G$92) -> 15 | F21: =IFERROR(COUNTIFS(Checklist!$I$73:$I$92,TRUE(),Checklist!$H$73:$H$92,TRUE())/COUNTIF(Checklist!$H$73:$H$92,TRUE()),0) -> 0 | G21: =UWorld!E15 -> 14 | H21: =UWorld!F15 -> 0
A22: 46154 | B22: Phys | C22: Hypothalamic-Pituitary-Thyroid Axis (TBL) | D22: =Planner!G16 -> Not Started | E22: =SUMPRODUCT(--(Checklist!$H$93:$H$98=TRUE()),Checklist!$G$93:$G$98) -> 15 | F22: =IFERROR(COUNTIFS(Checklist!$I$93:$I$98,TRUE(),Checklist!$H$93:$H$98,TRUE())/COUNTIF(Checklist!$H$93:$H$98,TRUE()),0) -> 0 | G22: =UWorld!E16 -> 0 | H22: =UWorld!F16 -> 0
A23: 46155 | B23: Path | C23: Thyroid & Parathyroid Pathology | D23: =Planner!G17 -> Not Started | E23: =SUMPRODUCT(--(Checklist!$H$99:$H$114=TRUE()),Checklist!$G$99:$G$114) -> 15 | F23: =IFERROR(COUNTIFS(Checklist!$I$99:$I$114,TRUE(),Checklist!$H$99:$H$114,TRUE())/COUNTIF(Checklist!$H$99:$H$114,TRUE()),0) -> 0 | G23: =UWorld!E17 -> 47 | H23: =UWorld!F17 -> 0
A24: 46156 | B24: Pharm | C24: Diagnosis & Treatment of Thyroid Disorders | D24: =Planner!G18 -> Not Started | E24: =SUMPRODUCT(--(Checklist!$H$115:$H$121=TRUE()),Checklist!$G$115:$G$121) -> 15 | F24: =IFERROR(COUNTIFS(Checklist!$I$115:$I$121,TRUE(),Checklist!$H$115:$H$121,TRUE())/COUNTIF(Checklist!$H$115:$H$121,TRUE()),0) -> 0 | G24: =UWorld!E18 -> 20 | H24: =UWorld!F18 -> 0
A25: 46162 | B25: Phys | C25: Hypothalamic-Pituitary-Adrenal Axis | D25: =Planner!G19 -> Not Started | E25: =SUMPRODUCT(--(Checklist!$H$122:$H$127=TRUE()),Checklist!$G$122:$G$127) -> 15 | F25: =IFERROR(COUNTIFS(Checklist!$I$122:$I$127,TRUE(),Checklist!$H$122:$H$127,TRUE())/COUNTIF(Checklist!$H$122:$H$127,TRUE()),0) -> 0 | G25: =UWorld!E19 -> 16 | H25: =UWorld!F19 -> 0
A26: 46161 | B26: Path | C26: Pathophysiology of Diabetes Mellitus | D26: =Planner!G20 -> Not Started | E26: =SUMPRODUCT(--(Checklist!$H$128:$H$134=TRUE()),Checklist!$G$128:$G$134) -> 15 | F26: =IFERROR(COUNTIFS(Checklist!$I$128:$I$134,TRUE(),Checklist!$H$128:$H$134,TRUE())/COUNTIF(Checklist!$H$128:$H$134,TRUE()),0) -> 0 | G26: =UWorld!E20 -> 49 | H26: =UWorld!F20 -> 0
A27: 46161 | B27: Pharm | C27: Diabetes Type 1 — Diagnosis & Treatment | D27: =Planner!G21 -> Not Started | E27: =SUMPRODUCT(--(Checklist!$H$135:$H$142=TRUE()),Checklist!$G$135:$G$142) -> 15 | F27: =IFERROR(COUNTIFS(Checklist!$I$135:$I$142,TRUE(),Checklist!$H$135:$H$142,TRUE())/COUNTIF(Checklist!$H$135:$H$142,TRUE()),0) -> 0 | G27: =UWorld!E21 -> 41 | H27: =UWorld!F21 -> 0
A28: 46161 | B28: Pharm | C28: Diabetes Type 2 — Diagnosis & Treatment | D28: =Planner!G22 -> Not Started | E28: =SUMPRODUCT(--(Checklist!$H$143:$H$148=TRUE()),Checklist!$G$143:$G$148) -> 15 | F28: =IFERROR(COUNTIFS(Checklist!$I$143:$I$148,TRUE(),Checklist!$H$143:$H$148,TRUE())/COUNTIF(Checklist!$H$143:$H$148,TRUE()),0) -> 0 | G28: =UWorld!E22 -> 41 | H28: =UWorld!F22 -> 0
A29: 46162 | B29: Path | C29: Adrenal Pathology | D29: =Planner!G23 -> Not Started | E29: =SUMPRODUCT(--(Checklist!$H$149:$H$156=TRUE()),Checklist!$G$149:$G$156) -> 15 | F29: =IFERROR(COUNTIFS(Checklist!$I$149:$I$156,TRUE(),Checklist!$H$149:$H$156,TRUE())/COUNTIF(Checklist!$H$149:$H$156,TRUE()),0) -> 0 | G29: =UWorld!E23 -> 29 | H29: =UWorld!F23 -> 0
A30: 46162 | B30: Pharm | C30: Diagnosis & Treatment of Adrenal Disorders | D30: =Planner!G24 -> Not Started | E30: =SUMPRODUCT(--(Checklist!$H$157:$H$163=TRUE()),Checklist!$G$157:$G$163) -> 15 | F30: =IFERROR(COUNTIFS(Checklist!$I$157:$I$163,TRUE(),Checklist!$H$157:$H$163,TRUE())/COUNTIF(Checklist!$H$157:$H$163,TRUE()),0) -> 0 | G30: =UWorld!E24 -> 16 | H30: =UWorld!F24 -> 0
A31: 46164 | B31: Pharm | C31: Case Discussion: Pituitary & Thyroid | D31: =Planner!G25 -> Not Started | E31: =SUMPRODUCT(--(Checklist!$H$164:$H$168=TRUE()),Checklist!$G$164:$G$168) -> 15 | F31: =IFERROR(COUNTIFS(Checklist!$I$164:$I$168,TRUE(),Checklist!$H$164:$H$168,TRUE())/COUNTIF(Checklist!$H$164:$H$168,TRUE()),0) -> 0 | G31: =UWorld!E25 -> 0 | H31: =UWorld!F25 -> 0
A32: 46169 | B32: Phys | C32: Stress, Stress Hormones & Pathophysiology | D32: =Planner!G26 -> Not Started | E32: =SUMPRODUCT(--(Checklist!$H$169:$H$172=TRUE()),Checklist!$G$169:$G$172) -> 15 | F32: =IFERROR(COUNTIFS(Checklist!$I$169:$I$172,TRUE(),Checklist!$H$169:$H$172,TRUE())/COUNTIF(Checklist!$H$169:$H$172,TRUE()),0) -> 0 | G32: =UWorld!E26 -> 1 | H32: =UWorld!F26 -> 0
A33: 46170 | B33: Path | C33: Endocrine Lab | D33: =Planner!G27 -> Not Started | E33: =SUMPRODUCT(--(Checklist!$H$173:$H$181=TRUE()),Checklist!$G$173:$G$181) -> 15 | F33: =IFERROR(COUNTIFS(Checklist!$I$173:$I$181,TRUE(),Checklist!$H$173:$H$181,TRUE())/COUNTIF(Checklist!$H$173:$H$181,TRUE()),0) -> 0 | G33: =UWorld!E27 -> 0 | H33: =UWorld!F27 -> 0
A34: 46170 | B34: Pharm | C34: Diabetes Clinical Cases | D34: =Planner!G28 -> Not Started | E34: =SUMPRODUCT(--(Checklist!$H$182:$H$187=TRUE()),Checklist!$G$182:$G$187) -> 15 | F34: =IFERROR(COUNTIFS(Checklist!$I$182:$I$187,TRUE(),Checklist!$H$182:$H$187,TRUE())/COUNTIF(Checklist!$H$182:$H$187,TRUE()),0) -> 0 | G34: =UWorld!E28 -> 1 | H34: =UWorld!F28 -> 0
A35: 46171 | B35: Pharm | C35: TBL — Pituitary & Thyroid Disorders | D35: =Planner!G29 -> Not Started | E35: =SUMPRODUCT(--(Checklist!$H$188:$H$191=TRUE()),Checklist!$G$188:$G$191) -> 15 | F35: =IFERROR(COUNTIFS(Checklist!$I$188:$I$191,TRUE(),Checklist!$H$188:$H$191,TRUE())/COUNTIF(Checklist!$H$188:$H$191,TRUE()),0) -> 0 | G35: =UWorld!E29 -> 0 | H35: =UWorld!F29 -> 0

Sheet Planner
A1: Planner
A2: Choose LEC plus up to 2 third-party resources per lecture. Progress updates everywhere else automatically.
A4: Date | B4: Subject | C4: Lecture | D4: Include LEC? | E4: Resource 1 | F4: Resource 2 | G4: Status | H4: Notes | I4: Est. Total Min | J4: Checklist Done | K4: Checklist Total | L4: Progress % | M4: Available 3rd-Party Resources
A5: 46132 | B5: Biochem | C5: Introduction to Hormones | D5: No | G5: Not Started | I5: =SUMPRODUCT(--(Checklist!$H$5:$H$8=TRUE()),Checklist!$G$5:$G$8) -> 15 | J5: =COUNTIFS(Checklist!$H$5:$H$8,TRUE(),Checklist!$I$5:$I$8,TRUE()) -> 0 | K5: =COUNTIF(Checklist!$H$5:$H$8,TRUE()) -> 1 | L5: =IFERROR(J5/K5,0) -> 0 | M5: Bootcamp, Boards & Beyond
A6: 46132 | B6: Phys | C6: Hypothalamic Pituitary Relationships I | D6: No | G6: Not Started | I6: =SUMPRODUCT(--(Checklist!$H$9:$H$14=TRUE()),Checklist!$G$9:$G$14) -> 15 | J6: =COUNTIFS(Checklist!$H$9:$H$14,TRUE(),Checklist!$I$9:$I$14,TRUE()) -> 0 | K6: =COUNTIF(Checklist!$H$9:$H$14,TRUE()) -> 1 | L6: =IFERROR(J6/K6,0) -> 0 | M6: Bootcamp, Boards & Beyond, Sketchy Pharm, Sketchy Path
A7: 46135 | B7: Biochem | C7: Adrenal Hormone Synthesis and Action | D7: No | G7: Not Started | I7: =SUMPRODUCT(--(Checklist!$H$15:$H$20=TRUE()),Checklist!$G$15:$G$20) -> 15 | J7: =COUNTIFS(Checklist!$H$15:$H$20,TRUE(),Checklist!$I$15:$I$20,TRUE()) -> 0 | K7: =COUNTIF(Checklist!$H$15:$H$20,TRUE()) -> 1 | L7: =IFERROR(J7/K7,0) -> 0 | M7: Bootcamp, Boards & Beyond, Sketchy Path
A8: 46135 | B8: Biochem | C8: Sex Steroid Synthesis and Action | D8: No | G8: Not Started | I8: =SUMPRODUCT(--(Checklist!$H$21:$H$25=TRUE()),Checklist!$G$21:$G$25) -> 15 | J8: =COUNTIFS(Checklist!$H$21:$H$25,TRUE(),Checklist!$I$21:$I$25,TRUE()) -> 0 | K8: =COUNTIF(Checklist!$H$21:$H$25,TRUE()) -> 1 | L8: =IFERROR(J8/K8,0) -> 0 | M8: Bootcamp, Boards & Beyond, Sketchy Pharm
A9: 46134 | B9: Phys | C9: Hypothalamic Pituitary Relationships II | D9: No | G9: Not Started | I9: =SUMPRODUCT(--(Checklist!$H$26:$H$32=TRUE()),Checklist!$G$26:$G$32) -> 15 | J9: =COUNTIFS(Checklist!$H$26:$H$32,TRUE(),Checklist!$I$26:$I$32,TRUE()) -> 0 | K9: =COUNTIF(Checklist!$H$26:$H$32,TRUE()) -> 1 | L9: =IFERROR(J9/K9,0) -> 0 | M9: Bootcamp, Boards & Beyond, Sketchy Pharm, Sketchy Path
A10: 46140 | B10: Biochem | C10: Posterior Pituitary Hormones | D10: No | G10: Not Started | I10: =SUMPRODUCT(--(Checklist!$H$33:$H$41=TRUE()),Checklist!$G$33:$G$41) -> 15 | J10: =COUNTIFS(Checklist!$H$33:$H$41,TRUE(),Checklist!$I$33:$I$41,TRUE()) -> 0 | K10: =COUNTIF(Checklist!$H$33:$H$41,TRUE()) -> 1 | L10: =IFERROR(J10/K10,0) -> 0 | M10: Bootcamp, Boards & Beyond, Sketchy Pharm, Sketchy Path
A11: 46141 | B11: Path | C11: Pituitary Pathology | D11: No | G11: Not Started | I11: =SUMPRODUCT(--(Checklist!$H$42:$H$49=TRUE()),Checklist!$G$42:$G$49) -> 15 | J11: =COUNTIFS(Checklist!$H$42:$H$49,TRUE(),Checklist!$I$42:$I$49,TRUE()) -> 0 | K11: =COUNTIF(Checklist!$H$42:$H$49,TRUE()) -> 1 | L11: =IFERROR(J11/K11,0) -> 0 | M11: Bootcamp, Pathoma, Boards & Beyond, Sketchy Path
A12: 46156 | B12: Pharm | C12: Diagnosis & Treatment of Pituitary Disorders | D12: No | G12: Not Started | I12: =SUMPRODUCT(--(Checklist!$H$50:$H$58=TRUE()),Checklist!$G$50:$G$58) -> 15 | J12: =COUNTIFS(Checklist!$H$50:$H$58,TRUE(),Checklist!$I$50:$I$58,TRUE()) -> 0 | K12: =COUNTIF(Checklist!$H$50:$H$58,TRUE()) -> 1 | L12: =IFERROR(J12/K12,0) -> 0 | M12: Bootcamp, Boards & Beyond, Sketchy Pharm, Sketchy Path
A13: 46157 | B13: Phys | C13: Hypothalamic-Pituitary-GH Axis | D13: No | G13: Not Started | I13: =SUMPRODUCT(--(Checklist!$H$59:$H$66=TRUE()),Checklist!$G$59:$G$66) -> 15 | J13: =COUNTIFS(Checklist!$H$59:$H$66,TRUE(),Checklist!$I$59:$I$66,TRUE()) -> 0 | K13: =COUNTIF(Checklist!$H$59:$H$66,TRUE()) -> 1 | L13: =IFERROR(J13/K13,0) -> 0 | M13: Bootcamp, Boards & Beyond, Sketchy Pharm, Sketchy Path
A14: 46154 | B14: Biochem | C14: Thyroid Hormone Synthesis and Action | D14: No | G14: Not Started | I14: =SUMPRODUCT(--(Checklist!$H$67:$H$72=TRUE()),Checklist!$G$67:$G$72) -> 15 | J14: =COUNTIFS(Checklist!$H$67:$H$72,TRUE(),Checklist!$I$67:$I$72,TRUE()) -> 0 | K14: =COUNTIF(Checklist!$H$67:$H$72,TRUE()) -> 1 | L14: =IFERROR(J14/K14,0) -> 0 | M14: Bootcamp, Boards & Beyond, Sketchy Path
A15: 46154 | B15: Hist | C15: Thyroid, Parathyroid & Adrenal Histology | D15: No | G15: Not Started | I15: =SUMPRODUCT(--(Checklist!$H$73:$H$92=TRUE()),Checklist!$G$73:$G$92) -> 15 | J15: =COUNTIFS(Checklist!$H$73:$H$92,TRUE(),Checklist!$I$73:$I$92,TRUE()) -> 0 | K15: =COUNTIF(Checklist!$H$73:$H$92,TRUE()) -> 1 | L15: =IFERROR(J15/K15,0) -> 0 | M15: Bootcamp, Pathoma, Boards & Beyond, Sketchy Pharm, Sketchy Path
A16: 46154 | B16: Phys | C16: Hypothalamic-Pituitary-Thyroid Axis (TBL) | D16: No | G16: Not Started | I16: =SUMPRODUCT(--(Checklist!$H$93:$H$98=TRUE()),Checklist!$G$93:$G$98) -> 15 | J16: =COUNTIFS(Checklist!$H$93:$H$98,TRUE(),Checklist!$I$93:$I$98,TRUE()) -> 0 | K16: =COUNTIF(Checklist!$H$93:$H$98,TRUE()) -> 1 | L16: =IFERROR(J16/K16,0) -> 0 | M16: Bootcamp, Boards & Beyond, Sketchy Path
A17: 46155 | B17: Path | C17: Thyroid & Parathyroid Pathology | D17: No | G17: Not Started | I17: =SUMPRODUCT(--(Checklist!$H$99:$H$114=TRUE()),Checklist!$G$99:$G$114) -> 15 | J17: =COUNTIFS(Checklist!$H$99:$H$114,TRUE(),Checklist!$I$99:$I$114,TRUE()) -> 0 | K17: =COUNTIF(Checklist!$H$99:$H$114,TRUE()) -> 1 | L17: =IFERROR(J17/K17,0) -> 0 | M17: Bootcamp, Pathoma, Boards & Beyond, Sketchy Pharm, Sketchy Path
A18: 46156 | B18: Pharm | C18: Diagnosis & Treatment of Thyroid Disorders | D18: No | G18: Not Started | I18: =SUMPRODUCT(--(Checklist!$H$115:$H$121=TRUE()),Checklist!$G$115:$G$121) -> 15 | J18: =COUNTIFS(Checklist!$H$115:$H$121,TRUE(),Checklist!$I$115:$I$121,TRUE()) -> 0 | K18: =COUNTIF(Checklist!$H$115:$H$121,TRUE()) -> 1 | L18: =IFERROR(J18/K18,0) -> 0 | M18: Bootcamp, Boards & Beyond, Sketchy Pharm, Sketchy Path
A19: 46162 | B19: Phys | C19: Hypothalamic-Pituitary-Adrenal Axis | D19: No | G19: Not Started | I19: =SUMPRODUCT(--(Checklist!$H$122:$H$127=TRUE()),Checklist!$G$122:$G$127) -> 15 | J19: =COUNTIFS(Checklist!$H$122:$H$127,TRUE(),Checklist!$I$122:$I$127,TRUE()) -> 0 | K19: =COUNTIF(Checklist!$H$122:$H$127,TRUE()) -> 1 | L19: =IFERROR(J19/K19,0) -> 0 | M19: Bootcamp, Boards & Beyond, Sketchy Path
A20: 46161 | B20: Path | C20: Pathophysiology of Diabetes Mellitus | D20: No | G20: Not Started | I20: =SUMPRODUCT(--(Checklist!$H$128:$H$134=TRUE()),Checklist!$G$128:$G$134) -> 15 | J20: =COUNTIFS(Checklist!$H$128:$H$134,TRUE(),Checklist!$I$128:$I$134,TRUE()) -> 0 | K20: =COUNTIF(Checklist!$H$128:$H$134,TRUE()) -> 1 | L20: =IFERROR(J20/K20,0) -> 0 | M20: Bootcamp, Pathoma, Boards & Beyond, Sketchy Path
A21: 46161 | B21: Pharm | C21: Diabetes Type 1 — Diagnosis & Treatment | D21: No | G21: Not Started | I21: =SUMPRODUCT(--(Checklist!$H$135:$H$142=TRUE()),Checklist!$G$135:$G$142) -> 15 | J21: =COUNTIFS(Checklist!$H$135:$H$142,TRUE(),Checklist!$I$135:$I$142,TRUE()) -> 0 | K21: =COUNTIF(Checklist!$H$135:$H$142,TRUE()) -> 1 | L21: =IFERROR(J21/K21,0) -> 0 | M21: Bootcamp, Boards & Beyond, Sketchy Pharm, Sketchy Path
A22: 46161 | B22: Pharm | C22: Diabetes Type 2 — Diagnosis & Treatment | D22: No | G22: Not Started | I22: =SUMPRODUCT(--(Checklist!$H$143:$H$148=TRUE()),Checklist!$G$143:$G$148) -> 15 | J22: =COUNTIFS(Checklist!$H$143:$H$148,TRUE(),Checklist!$I$143:$I$148,TRUE()) -> 0 | K22: =COUNTIF(Checklist!$H$143:$H$148,TRUE()) -> 1 | L22: =IFERROR(J22/K22,0) -> 0 | M22: Bootcamp, Boards & Beyond, Sketchy Pharm
A23: 46162 | B23: Path | C23: Adrenal Pathology | D23: No | G23: Not Started | I23: =SUMPRODUCT(--(Checklist!$H$149:$H$156=TRUE()),Checklist!$G$149:$G$156) -> 15 | J23: =COUNTIFS(Checklist!$H$149:$H$156,TRUE(),Checklist!$I$149:$I$156,TRUE()) -> 0 | K23: =COUNTIF(Checklist!$H$149:$H$156,TRUE()) -> 1 | L23: =IFERROR(J23/K23,0) -> 0 | M23: Bootcamp, Pathoma, Boards & Beyond, Sketchy Pharm, Sketchy Path
A24: 46162 | B24: Pharm | C24: Diagnosis & Treatment of Adrenal Disorders | D24: No | G24: Not Started | I24: =SUMPRODUCT(--(Checklist!$H$157:$H$163=TRUE()),Checklist!$G$157:$G$163) -> 15 | J24: =COUNTIFS(Checklist!$H$157:$H$163,TRUE(),Checklist!$I$157:$I$163,TRUE()) -> 0 | K24: =COUNTIF(Checklist!$H$157:$H$163,TRUE()) -> 1 | L24: =IFERROR(J24/K24,0) -> 0 | M24: Bootcamp, Boards & Beyond, Sketchy Pharm, Sketchy Path
A25: 46164 | B25: Pharm | C25: Case Discussion: Pituitary & Thyroid | D25: No | G25: Not Started | I25: =SUMPRODUCT(--(Checklist!$H$164:$H$168=TRUE()),Checklist!$G$164:$G$168) -> 15 | J25: =COUNTIFS(Checklist!$H$164:$H$168,TRUE(),Checklist!$I$164:$I$168,TRUE()) -> 0 | K25: =COUNTIF(Checklist!$H$164:$H$168,TRUE()) -> 1 | L25: =IFERROR(J25/K25,0) -> 0 | M25: Bootcamp, Boards & Beyond
A26: 46169 | B26: Phys | C26: Stress, Stress Hormones & Pathophysiology | D26: No | G26: Not Started | I26: =SUMPRODUCT(--(Checklist!$H$169:$H$172=TRUE()),Checklist!$G$169:$G$172) -> 15 | J26: =COUNTIFS(Checklist!$H$169:$H$172,TRUE(),Checklist!$I$169:$I$172,TRUE()) -> 0 | K26: =COUNTIF(Checklist!$H$169:$H$172,TRUE()) -> 1 | L26: =IFERROR(J26/K26,0) -> 0 | M26: Bootcamp, Boards & Beyond
A27: 46170 | B27: Path | C27: Endocrine Lab | D27: No | G27: Not Started | I27: =SUMPRODUCT(--(Checklist!$H$173:$H$181=TRUE()),Checklist!$G$173:$G$181) -> 15 | J27: =COUNTIFS(Checklist!$H$173:$H$181,TRUE(),Checklist!$I$173:$I$181,TRUE()) -> 0 | K27: =COUNTIF(Checklist!$H$173:$H$181,TRUE()) -> 1 | L27: =IFERROR(J27/K27,0) -> 0 | M27: Bootcamp, Pathoma, Sketchy Path
A28: 46170 | B28: Pharm | C28: Diabetes Clinical Cases | D28: No | G28: Not Started | I28: =SUMPRODUCT(--(Checklist!$H$182:$H$187=TRUE()),Checklist!$G$182:$G$187) -> 15 | J28: =COUNTIFS(Checklist!$H$182:$H$187,TRUE(),Checklist!$I$182:$I$187,TRUE()) -> 0 | K28: =COUNTIF(Checklist!$H$182:$H$187,TRUE()) -> 1 | L28: =IFERROR(J28/K28,0) -> 0 | M28: Bootcamp, Boards & Beyond, Sketchy Pharm
A29: 46171 | B29: Pharm | C29: TBL — Pituitary & Thyroid Disorders | D29: No | G29: Not Started | I29: =SUMPRODUCT(--(Checklist!$H$188:$H$191=TRUE()),Checklist!$G$188:$G$191) -> 15 | J29: =COUNTIFS(Checklist!$H$188:$H$191,TRUE(),Checklist!$I$188:$I$191,TRUE()) -> 0 | K29: =COUNTIF(Checklist!$H$188:$H$191,TRUE()) -> 1 | L29: =IFERROR(J29/K29,0) -> 0 | M29: Bootcamp, Boards & Beyond

Sheet Checklist
A1: Checklist
A2: Mark Done? = TRUE as you complete tasks. Included? updates automatically from the Planner tab.
A4: Date | B4: Subject | C4: Lecture | D4: Sort | E4: Item Type | F4: Task / Resource | G4: Est. Min | H4: Included? | I4: Done? | J4: Notes
A5: 46132 | B5: Biochem | C5: Introduction to Hormones | D5: 1 | E5: MNTS | F5: Reviewed MNTS | G5: 15 | H5: =TRUE() -> TRUE | I5: =FALSE() -> FALSE
A6: 46132 | B6: Biochem | C6: Introduction to Hormones | D6: 2 | E6: LEC | F6: Lecture Notes | G6: 60 | H6: =Planner!$D5="Yes" -> FALSE | I6: =FALSE() -> FALSE
A7: 46132 | B7: Biochem | C7: Introduction to Hormones | D7: 3 | E7: Bootcamp | F7: Fundamental Principles of Endocrinology (Ch. 1) | G7: 29 | H7: =OR(Planner!$E$5=$E7,Planner!$F$5=$E7) -> FALSE | I7: =FALSE() -> FALSE
A8: 46132 | B8: Biochem | C8: Introduction to Hormones | D8: 3 | E8: Boards & Beyond | F8: Pituitary Gland (Ch. 5) | G8: 28 | H8: =OR(Planner!$E$5=$E8,Planner!$F$5=$E8) -> FALSE | I8: =FALSE() -> FALSE
A9: 46132 | B9: Phys | C9: Hypothalamic Pituitary Relationships I | D9: 1 | E9: MNTS | F9: Reviewed MNTS | G9: 15 | H9: =TRUE() -> TRUE | I9: =FALSE() -> FALSE
A10: 46132 | B10: Phys | C10: Hypothalamic Pituitary Relationships I | D10: 2 | E10: LEC | F10: Lecture Notes | G10: 60 | H10: =Planner!$D6="Yes" -> FALSE | I10: =FALSE() -> FALSE
A11: 46132 | B11: Phys | C11: Hypothalamic Pituitary Relationships I | D11: 3 | E11: Bootcamp | F11: Fundamental Principles of Endocrinology (Ch. 1) | G11: 29 | H11: =OR(Planner!$E$6=$E11,Planner!$F$6=$E11) -> FALSE | I11: =FALSE() -> FALSE
A12: 46132 | B12: Phys | C12: Hypothalamic Pituitary Relationships I | D12: 3 | E12: Boards & Beyond | F12: Pituitary Gland (Ch. 5) | G12: 28 | H12: =OR(Planner!$E$6=$E12,Planner!$F$6=$E12) -> FALSE | I12: =FALSE() -> FALSE
A13: 46132 | B13: Phys | C13: Hypothalamic Pituitary Relationships I | D13: 3 | E13: Sketchy Path | F13: Pituitary Dysfunction: Etiologies — “Million Dollar Pituitary” | G13: 12 | H13: =OR(Planner!$E$6=$E13,Planner!$F$6=$E13) -> FALSE | I13: =FALSE() -> FALSE
A14: 46132 | B14: Phys | C14: Hypothalamic Pituitary Relationships I | D14: 3 | E14: Sketchy Path | F14: Pituitary Dysfunction: Clinical — “Rocky Pituitary” | G14: 25 | H14: =OR(Planner!$E$6=$E14,Planner!$F$6=$E14) -> FALSE | I14: =FALSE() -> FALSE
A15: 46135 | B15: Biochem | C15: Adrenal Hormone Synthesis and Action | D15: 1 | E15: MNTS | F15: Reviewed MNTS | G15: 15 | H15: =TRUE() -> TRUE | I15: =FALSE() -> FALSE
A16: 46135 | B16: Biochem | C16: Adrenal Hormone Synthesis and Action | D16: 2 | E16: LEC | F16: Lecture Notes | G16: 60 | H16: =Planner!$D7="Yes" -> FALSE | I16: =FALSE() -> FALSE
A17: 46135 | B17: Biochem | C17: Adrenal Hormone Synthesis and Action | D17: 3 | E17: Bootcamp | F17: Adrenal Glands (Ch. 6) | G17: 153 | H17: =OR(Planner!$E$7=$E17,Planner!$F$7=$E17) -> FALSE | I17: =FALSE() -> FALSE
A18: 46135 | B18: Biochem | C18: Adrenal Hormone Synthesis and Action | D18: 3 | E18: Boards & Beyond | F18: Adrenals (Ch. 2) | G18: 72 | H18: =OR(Planner!$E$7=$E18,Planner!$F$7=$E18) -> FALSE | I18: =FALSE() -> FALSE
A19: 46135 | B19: Biochem | C19: Adrenal Hormone Synthesis and Action | D19: 3 | E19: Sketchy Path | F19: Adrenal Insufficiency — “Hollywood Hypofunction” | G19: 22 | H19: =OR(Planner!$E$7=$E19,Planner!$F$7=$E19) -> FALSE | I19: =FALSE() -> FALSE
A20: 46135 | B20: Biochem | C20: Adrenal Hormone Synthesis and Action | D20: 3 | E20: Sketchy Path | F20: CAH — “Thank you Desmond, but our cortisol is in another adrenal!” | G20: 25 | H20: =OR(Planner!$E$7=$E20,Planner!$F$7=$E20) -> FALSE | I20: =FALSE() -> FALSE
A21: 46135 | B21: Biochem | C21: Sex Steroid Synthesis and Action | D21: 1 | E21: MNTS | F21: Reviewed MNTS | G21: 15 | H21: =TRUE() -> TRUE | I21: =FALSE() -> FALSE
A22: 46135 | B22: Biochem | C22: Sex Steroid Synthesis and Action | D22: 2 | E22: LEC | F22: Lecture Notes | G22: 60 | H22: =Planner!$D8="Yes" -> FALSE | I22: =FALSE() -> FALSE
A23: 46135 | B23: Biochem | C23: Sex Steroid Synthesis and Action | D23: 3 | E23: Bootcamp | F23: Adrenal Glands (Ch. 6) | G23: 153 | H23: =OR(Planner!$E$8=$E23,Planner!$F$8=$E23) -> FALSE | I23: =FALSE() -> FALSE
A24: 46135 | B24: Biochem | C24: Sex Steroid Synthesis and Action | D24: 3 | E24: Boards & Beyond | F24: Adrenals (Ch. 2) | G24: 72 | H24: =OR(Planner!$E$8=$E24,Planner!$F$8=$E24) -> FALSE | I24: =FALSE() -> FALSE
A25: 46135 | B25: Biochem | C25: Sex Steroid Synthesis and Action | D25: 3 | E25: Boards & Beyond | F25: Reproductive Hormones (Ch. 4) | G25: 57 | H25: =OR(Planner!$E$8=$E25,Planner!$F$8=$E25) -> FALSE | I25: =FALSE() -> FALSE
A26: 46134 | B26: Phys | C26: Hypothalamic Pituitary Relationships II | D26: 1 | E26: MNTS | F26: Reviewed MNTS | G26: 15 | H26: =TRUE() -> TRUE | I26: =FALSE() -> FALSE
A27: 46134 | B27: Phys | C27: Hypothalamic Pituitary Relationships II | D27: 2 | E27: LEC | F27: Lecture Notes | G27: 60 | H27: =Planner!$D9="Yes" -> FALSE | I27: =FALSE() -> FALSE
A28: 46134 | B28: Phys | C28: Hypothalamic Pituitary Relationships II | D28: 3 | E28: Bootcamp | F28: Hypothalamus & Pituitary (Ch. 2–3) | G28: 77 | H28: =OR(Planner!$E$9=$E28,Planner!$F$9=$E28) -> FALSE | I28: =FALSE() -> FALSE
A29: 46134 | B29: Phys | C29: Hypothalamic Pituitary Relationships II | D29: 3 | E29: Boards & Beyond | F29: Pituitary Gland (Ch. 5) | G29: 28 | H29: =OR(Planner!$E$9=$E29,Planner!$F$9=$E29) -> FALSE | I29: =FALSE() -> FALSE
A30: 46134 | B30: Phys | C30: Hypothalamic Pituitary Relationships II | D30: 3 | E30: Boards & Beyond | F30: Reproductive Hormones (Ch. 4) | G30: 57 | H30: =OR(Planner!$E$9=$E30,Planner!$F$9=$E30) -> FALSE | I30: =FALSE() -> FALSE
A31: 46134 | B31: Phys | C31: Hypothalamic Pituitary Relationships II | D31: 3 | E31: Sketchy Path | F31: Pituitary Dysfunction: Etiologies — “Million Dollar Pituitary” | G31: 12 | H31: =OR(Planner!$E$9=$E31,Planner!$F$9=$E31) -> FALSE | I31: =FALSE() -> FALSE
A32: 46134 | B32: Phys | C32: Hypothalamic Pituitary Relationships II | D32: 3 | E32: Sketchy Path | F32: Pituitary Dysfunction: Clinical — “Rocky Pituitary” | G32: 25 | H32: =OR(Planner!$E$9=$E32,Planner!$F$9=$E32) -> FALSE | I32: =FALSE() -> FALSE
A33: 46140 | B33: Biochem | C33: Posterior Pituitary Hormones | D33: 1 | E33: MNTS | F33: Reviewed MNTS | G33: 15 | H33: =TRUE() -> TRUE | I33: =FALSE() -> FALSE
A34: 46140 | B34: Biochem | C34: Posterior Pituitary Hormones | D34: 2 | E34: LEC | F34: Lecture Notes | G34: 60 | H34: =Planner!$D10="Yes" -> FALSE | I34: =FALSE() -> FALSE
A35: 46140 | B35: Biochem | C35: Posterior Pituitary Hormones | D35: 3 | E35: Bootcamp | F35: Hypothalamus & Pituitary (Ch. 2–3) | G35: 77 | H35: =OR(Planner!$E$10=$E35,Planner!$F$10=$E35) -> FALSE | I35: =FALSE() -> FALSE
A36: 46140 | B36: Biochem | C36: Posterior Pituitary Hormones | D36: 3 | E36: Boards & Beyond | F36: Pituitary Gland (Ch. 5) | G36: 28 | H36: =OR(Planner!$E$10=$E36,Planner!$F$10=$E36) -> FALSE | I36: =FALSE() -> FALSE
A37: 46140 | B37: Biochem | C37: Posterior Pituitary Hormones | D37: 3 | E37: Sketchy Pharm | F37: ADH, DDAVP, ADH Antagonists — “Water Hazard” | G37: 19 | H37: =OR(Planner!$E$10=$E37,Planner!$F$10=$E37) -> FALSE | I37: =FALSE() -> FALSE
A38: 46140 | B38: Biochem | C38: Posterior Pituitary Hormones | D38: 3 | E38: Sketchy Pharm | F38: GH, Octreotide, Pegvisomant — “Jak Stat and the Beanstalk” | G38: 18 | H38: =OR(Planner!$E$10=$E38,Planner!$F$10=$E38) -> FALSE | I38: =FALSE() -> FALSE
A39: 46140 | B39: Biochem | C39: Posterior Pituitary Hormones | D39: 3 | E39: Sketchy Path | F39: Pituitary Dysfunction: Etiologies — “Million Dollar Pituitary” | G39: 12 | H39: =OR(Planner!$E$10=$E39,Planner!$F$10=$E39) -> FALSE | I39: =FALSE() -> FALSE
A40: 46140 | B40: Biochem | C40: Posterior Pituitary Hormones | D40: 3 | E40: Sketchy Path | F40: Pituitary Dysfunction: Clinical — “Rocky Pituitary” | G40: 25 | H40: =OR(Planner!$E$10=$E40,Planner!$F$10=$E40) -> FALSE | I40: =FALSE() -> FALSE
A41: 46140 | B41: Biochem | C41: Posterior Pituitary Hormones | D41: 3 | E41: Sketchy Path | F41: Diabetes Insipidus & SIADH — “Acqua Gialla Della Vita” | G41: 27 | H41: =OR(Planner!$E$10=$E41,Planner!$F$10=$E41) -> FALSE | I41: =FALSE() -> FALSE
...

Sheet UWorld
A1: UWorld
A2: Enter question progress by lecture. Assigned counts are pre-filled from the HTML tracker.
A4: Lecture ID | B4: Date | C4: Subject | D4: Lecture | E4: Assigned Qs | F4: Done Qs | G4: % Complete | H4: % Correct | I4: Notes
A5: pl1 | B5: 46132 | C5: Biochem | D5: Introduction to Hormones | E5: 42 | F5: 0 | G5: =IFERROR(F5/E5,0) -> 0
A6: pl2 | B6: 46132 | C6: Phys | D6: Hypothalamic Pituitary Relationships I | E6: 4 | F6: 0 | G6: =IFERROR(F6/E6,0) -> 0
A7: pl3 | B7: 46135 | C7: Biochem | D7: Adrenal Hormone Synthesis and Action | E7: 11 | F7: 0 | G7: =IFERROR(F7/E7,0) -> 0
A8: pl4 | B8: 46135 | C8: Biochem | D8: Sex Steroid Synthesis and Action | E8: 14 | F8: 0 | G8: =IFERROR(F8/E8,0) -> 0
A9: pl5 | B9: 46134 | C9: Phys | D9: Hypothalamic Pituitary Relationships II | E9: 4 | F9: 0 | G9: =IFERROR(F9/E9,0) -> 0
A10: pl6 | B10: 46140 | C10: Biochem | D10: Posterior Pituitary Hormones | E10: 5 | F10: 0 | G10: =IFERROR(F10/E10,0) -> 0
A11: pl7 | B11: 46141 | C11: Path | D11: Pituitary Pathology | E11: 17 | F11: 0 | G11: =IFERROR(F11/E11,0) -> 0
A12: pl8 | B12: 46156 | C12: Pharm | D12: Diagnosis & Treatment of Pituitary Disorders | E12: 17 | F12: 0 | G12: =IFERROR(F12/E12,0) -> 0
A13: pl9 | B13: 46157 | C13: Phys | D13: Hypothalamic-Pituitary-GH Axis | E13: 2 | F13: 0 | G13: =IFERROR(F13/E13,0) -> 0
A14: pl10 | B14: 46154 | C14: Biochem | D14: Thyroid Hormone Synthesis and Action | E14: 1 | F14: 0 | G14: =IFERROR(F14/E14,0) -> 0
A15: pl11 | B15: 46154 | C15: Hist | D15: Thyroid, Parathyroid & Adrenal Histology | E15: 14 | F15: 0 | G15: =IFERROR(F15/E15,0) -> 0
A16: pl12 | B16: 46154 | C16: Phys | D16: Hypothalamic-Pituitary-Thyroid Axis (TBL) | E16: 0 | F16: 0 | G16: =IFERROR(F16/E16,0) -> 0
... A29: pl25 | B29: 46171 | C29: Pharm | D29: TBL — Pituitary & Thyroid Disorders | E29: 0 | F29: 0 | G29: =IFERROR(F29/E29,0) -> 0
D30: TOTAL | E30: =SUM(E5:E29) -> 392 | F30: =SUM(F5:F29) -> 0 | G30: =IFERROR(F30/E30,0) -> 0

Sheet QID Reference
A1: QID Reference
A2: Subtopic-level UWorld question IDs from the HTML tracker.
A4: Section | B4: Subtopic | C4: Question Count | D4: QIDs | E4: Color Tag
A5: Pituitary | B5: Pituitary Gland | C5: 17 | D5: 8702, 15303, 1152, 18948, 224, 15209, 1561, 18553, 214, 213, 1379, 225, 210, 206, 20588, 7670, 7671 | E5: #9333ea
A6: Thyroid & Parathyroid | B6: Thyroid Gland | C6: 15 | D6: 1213, 19754, 15028, 1407, 19752, 772, 1615, 770, 14985, 20168, 763, 19746, 767, 19753, 626 | E6: #2563eb
A7: Thyroid & Parathyroid | B7: Thyroid Disorders | C7: 14 | D7: 768, 14953, 20375, 983, 764, 769, 19747, 19946, 20146, 622, 14951, 1945, 19745, 12512 | E7: #2563eb
A8: Thyroid & Parathyroid | B8: Thyroid Cancer | C8: 2 | D8: 17236, 1747 | E8: #2563eb
A9: Thyroid & Parathyroid | B9: Parathyroid Glands | C9: 18 | D9: 641, 15270, 15289, 18863, 631, 11977, 795, 19947, 992, 15291, 640, 1686, 11660, 22188, 543, 979, 978, 15280 | E9: #2563eb
A10: Adrenal | B10: Adrenal Glands | C10: 13 | D10: 21524, 549, 8424, 18801, 687, 18803, 1773, 17247, 19975, 14899, 989, 608, 609 | E10: #dc2626
A11: Adrenal | B11: Congenital Adrenal Hyperplasia | C11: 6 | D11: 2080, 2081, 924, 19030, 610, 930 | E11: #dc2626
A12: Adrenal | B12: Adrenal Disorders | C12: 10 | D12: 1263, 17246, 454, 928, 295, 1921, 931, 927, 152, 932 | E12: #dc2626
A13: Diabetes & Glucose | B13: Endocrine Pancreas | C13: 4 | D13: 1768, 15881, 585, 1121 | E13: #ea6c0a
A14: Diabetes & Glucose | B14: Diabetes | C14: 17 | D14: 846, 1913, 848, 11040, 1012, 107, 985, 1011, 1996, 15675, 106, 15668, 18951, 1059, 921, 19407, 15652 | E14: #ea6c0a
A15: Diabetes & Glucose | B15: Insulin | C15: 4 | D15: 600, 15876, 850, 1324 | E15: #ea6c0a
A16: Diabetes & Glucose | B16: Treatment of Diabetes | C16: 17 | D16: 920, 6772, 11565, 18952, 18956, 18457, 16324, 15770, 15308, 18958, 1984, 14136, 8531, 607, 606, 1655, 604 | E16: #ea6c0a
... A22: Misc. Endocrine | B22: Signaling Pathways | C22: 4 | D22: 1720, 143, 995, 1122 | E22: #d97706
